<?xml version="1.0" encoding="UTF-8"?>
<testng-results retried="2" ignored="2" total="9" passed="3" failed="2" skipped="0">
  <reporter-output>
  </reporter-output>
  <suite started-at="2024-03-20T10:20:07 EDT" name="Suite" finished-at="2024-03-20T10:20:25 EDT" duration-ms="18609">
    <groups>
    </groups>
    <test started-at="2024-03-20T10:20:07 EDT" name="E2E as Test" finished-at="2024-03-20T10:20:23 EDT" duration-ms="15993">
      <class name="Automation4ME.tests.HomeTest">
        <test-method is-config="true" signature="launchApplication()[pri:0, instance:Automation4ME.tests.HomeTest@1c93f6e1]" started-at="2024-03-20T10:20:07 EDT" name="launchApplication" finished-at="2024-03-20T10:20:12 EDT" duration-ms="5333" status="PASS">
          <reporter-output>
          </reporter-output>
        </test-method> <!-- launchApplication -->
        <test-method signature="E2E(java.util.HashMap)[pri:0, instance:Automation4ME.tests.HomeTest@1c93f6e1]" started-at="2024-03-20T10:20:12 EDT" name="E2E" data-provider="getData1" finished-at="2024-03-20T10:20:14 EDT" duration-ms="1504" status="PASS">
          <params>
            <param index="0">
              <value>
                <![CDATA[{password=secret_sauce, email=standard_user}]]>
              </value>
            </param>
          </params>
          <reporter-output>
          </reporter-output>
        </test-method> <!-- E2E -->
        <test-method is-config="true" signature="teardown()[pri:0, instance:Automation4ME.tests.HomeTest@1c93f6e1]" started-at="2024-03-20T10:20:14 EDT" name="teardown" finished-at="2024-03-20T10:20:14 EDT" duration-ms="180" status="PASS">
          <reporter-output>
          </reporter-output>
        </test-method> <!-- teardown -->
        <test-method is-config="true" signature="launchApplication()[pri:0, instance:Automation4ME.tests.HomeTest@1c93f6e1]" started-at="2024-03-20T10:20:14 EDT" name="launchApplication" finished-at="2024-03-20T10:20:17 EDT" duration-ms="3015" status="PASS">
          <reporter-output>
          </reporter-output>
        </test-method> <!-- launchApplication -->
        <test-method signature="E2E(java.util.HashMap)[pri:0, instance:Automation4ME.tests.HomeTest@1c93f6e1]" started-at="2024-03-20T10:20:17 EDT" name="E2E" data-provider="getData1" finished-at="2024-03-20T10:20:18 EDT" duration-ms="1368" status="PASS">
          <params>
            <param index="0">
              <value>
                <![CDATA[{password=secret_sauce, email=standard_user}]]>
              </value>
            </param>
          </params>
          <reporter-output>
          </reporter-output>
        </test-method> <!-- E2E -->
        <test-method is-config="true" signature="teardown()[pri:0, instance:Automation4ME.tests.HomeTest@1c93f6e1]" started-at="2024-03-20T10:20:18 EDT" name="teardown" finished-at="2024-03-20T10:20:18 EDT" duration-ms="132" status="PASS">
          <reporter-output>
          </reporter-output>
        </test-method> <!-- teardown -->
        <test-method is-config="true" signature="launchApplication()[pri:0, instance:Automation4ME.tests.HomeTest@1c93f6e1]" started-at="2024-03-20T10:20:18 EDT" name="launchApplication" finished-at="2024-03-20T10:20:22 EDT" duration-ms="3378" status="PASS">
          <reporter-output>
          </reporter-output>
        </test-method> <!-- launchApplication -->
        <test-method signature="closingApplication()[pri:0, instance:Automation4ME.tests.HomeTest@1c93f6e1]" started-at="2024-03-20T10:20:22 EDT" name="closingApplication" finished-at="2024-03-20T10:20:23 EDT" duration-ms="835" status="PASS">
          <reporter-output>
          </reporter-output>
        </test-method> <!-- closingApplication -->
        <test-method is-config="true" signature="teardown()[pri:0, instance:Automation4ME.tests.HomeTest@1c93f6e1]" started-at="2024-03-20T10:20:23 EDT" name="teardown" finished-at="2024-03-20T10:20:23 EDT" duration-ms="141" status="PASS">
          <reporter-output>
          </reporter-output>
        </test-method> <!-- teardown -->
      </class> <!-- Automation4ME.tests.HomeTest -->
    </test> <!-- E2E as Test -->
    <test started-at="2024-03-20T10:20:07 EDT" name="Error Test" finished-at="2024-03-20T10:20:25 EDT" duration-ms="18609">
      <class name="Automation4ME.tests.ErrorValidationtest">
        <test-method is-config="true" signature="launchApplication()[pri:0, instance:Automation4ME.tests.ErrorValidationtest@27d4a09]" started-at="2024-03-20T10:20:07 EDT" name="launchApplication" finished-at="2024-03-20T10:20:12 EDT" duration-ms="5256" status="PASS">
          <reporter-output>
          </reporter-output>
        </test-method> <!-- launchApplication -->
        <test-method retried="true" signature="Errors(java.util.HashMap)[pri:0, instance:Automation4ME.tests.ErrorValidationtest@27d4a09]" started-at="2024-03-20T10:20:12 EDT" name="Errors" data-provider="getData1" finished-at="2024-03-20T10:20:13 EDT" duration-ms="779" status="SKIP">
          <params>
            <param index="0">
              <value>
                <![CDATA[{password=secret_sauce, email=standard_user}]]>
              </value>
            </param>
          </params>
          <exception class="java.lang.AssertionError">
            <message>
              <![CDATA[expected [false] but found [true]]]>
            </message>
            <full-stacktrace>
              <![CDATA[java.lang.AssertionError: expected [false] but found [true]
at org.testng.Assert.fail(Assert.java:111)
at org.testng.Assert.failNotEquals(Assert.java:1578)
at org.testng.Assert.assertFalse(Assert.java:79)
at org.testng.Assert.assertFalse(Assert.java:89)
at Automation4ME.tests.ErrorValidationtest.Errors(ErrorValidationtest.java:38)
at java.base/jdk.internal.reflect.NativeMethodAccessorImpl.invoke0(Native Method)
at java.base/jdk.internal.reflect.NativeMethodAccessorImpl.invoke(NativeMethodAccessorImpl.java:62)
at java.base/jdk.internal.reflect.DelegatingMethodAccessorImpl.invoke(DelegatingMethodAccessorImpl.java:43)
at java.base/java.lang.reflect.Method.invoke(Method.java:566)
at org.testng.internal.invokers.MethodInvocationHelper.invokeMethod(MethodInvocationHelper.java:139)
at org.testng.internal.invokers.TestInvoker.invokeMethod(TestInvoker.java:664)
at org.testng.internal.invokers.TestInvoker.invokeTestMethod(TestInvoker.java:228)
at org.testng.internal.invokers.MethodRunner.runInSequence(MethodRunner.java:63)
at org.testng.internal.invokers.TestInvoker$MethodInvocationAgent.invoke(TestInvoker.java:961)
at org.testng.internal.invokers.TestInvoker.invokeTestMethods(TestInvoker.java:201)
at org.testng.internal.invokers.TestMethodWorker.invokeTestMethods(TestMethodWorker.java:148)
at org.testng.internal.invokers.TestMethodWorker.run(TestMethodWorker.java:128)
at java.base/java.util.ArrayList.forEach(ArrayList.java:1541)
at org.testng.TestRunner.privateRun(TestRunner.java:819)
at org.testng.TestRunner.run(TestRunner.java:619)
at org.testng.SuiteRunner.runTest(SuiteRunner.java:443)
at org.testng.SuiteRunner$SuiteWorker.run(SuiteRunner.java:481)
at org.testng.internal.thread.ThreadUtil.lambda$execute$0(ThreadUtil.java:58)
at java.base/java.util.concurrent.FutureTask.run(FutureTask.java:264)
at java.base/java.util.concurrent.ThreadPoolExecutor.runWorker(ThreadPoolExecutor.java:1128)
at java.base/java.util.concurrent.ThreadPoolExecutor$Worker.run(ThreadPoolExecutor.java:628)
at java.base/java.lang.Thread.run(Thread.java:834)
]]>
            </full-stacktrace>
          </exception> <!-- java.lang.AssertionError -->
          <reporter-output>
          </reporter-output>
        </test-method> <!-- Errors -->
        <test-method is-config="true" signature="teardown()[pri:0, instance:Automation4ME.tests.ErrorValidationtest@27d4a09]" started-at="2024-03-20T10:20:13 EDT" name="teardown" finished-at="2024-03-20T10:20:13 EDT" duration-ms="204" status="PASS">
          <reporter-output>
          </reporter-output>
        </test-method> <!-- teardown -->
        <test-method is-config="true" signature="launchApplication()[pri:0, instance:Automation4ME.tests.ErrorValidationtest@27d4a09]" started-at="2024-03-20T10:20:13 EDT" name="launchApplication" finished-at="2024-03-20T10:20:16 EDT" duration-ms="2999" status="PASS">
          <reporter-output>
          </reporter-output>
        </test-method> <!-- launchApplication -->
        <test-method retried="true" signature="Errors(java.util.HashMap)[pri:0, instance:Automation4ME.tests.ErrorValidationtest@27d4a09]" started-at="2024-03-20T10:20:16 EDT" name="Errors" data-provider="getData1" finished-at="2024-03-20T10:20:17 EDT" duration-ms="710" status="SKIP">
          <params>
            <param index="0">
              <value>
                <![CDATA[{password=secret_sauce, email=standard_user}]]>
              </value>
            </param>
          </params>
          <exception class="java.lang.AssertionError">
            <message>
              <![CDATA[expected [false] but found [true]]]>
            </message>
            <full-stacktrace>
              <![CDATA[java.lang.AssertionError: expected [false] but found [true]
at org.testng.Assert.fail(Assert.java:111)
at org.testng.Assert.failNotEquals(Assert.java:1578)
at org.testng.Assert.assertFalse(Assert.java:79)
at org.testng.Assert.assertFalse(Assert.java:89)
at Automation4ME.tests.ErrorValidationtest.Errors(ErrorValidationtest.java:38)
at java.base/jdk.internal.reflect.NativeMethodAccessorImpl.invoke0(Native Method)
at java.base/jdk.internal.reflect.NativeMethodAccessorImpl.invoke(NativeMethodAccessorImpl.java:62)
at java.base/jdk.internal.reflect.DelegatingMethodAccessorImpl.invoke(DelegatingMethodAccessorImpl.java:43)
at java.base/java.lang.reflect.Method.invoke(Method.java:566)
at org.testng.internal.invokers.MethodInvocationHelper.invokeMethod(MethodInvocationHelper.java:139)
at org.testng.internal.invokers.TestInvoker.invokeMethod(TestInvoker.java:664)
at org.testng.internal.invokers.TestInvoker.retryFailed(TestInvoker.java:249)
at org.testng.internal.invokers.MethodRunner.runInSequence(MethodRunner.java:76)
at org.testng.internal.invokers.TestInvoker$MethodInvocationAgent.invoke(TestInvoker.java:961)
at org.testng.internal.invokers.TestInvoker.invokeTestMethods(TestInvoker.java:201)
at org.testng.internal.invokers.TestMethodWorker.invokeTestMethods(TestMethodWorker.java:148)
at org.testng.internal.invokers.TestMethodWorker.run(TestMethodWorker.java:128)
at java.base/java.util.ArrayList.forEach(ArrayList.java:1541)
at org.testng.TestRunner.privateRun(TestRunner.java:819)
at org.testng.TestRunner.run(TestRunner.java:619)
at org.testng.SuiteRunner.runTest(SuiteRunner.java:443)
at org.testng.SuiteRunner$SuiteWorker.run(SuiteRunner.java:481)
at org.testng.internal.thread.ThreadUtil.lambda$execute$0(ThreadUtil.java:58)
at java.base/java.util.concurrent.FutureTask.run(FutureTask.java:264)
at java.base/java.util.concurrent.ThreadPoolExecutor.runWorker(ThreadPoolExecutor.java:1128)
at java.base/java.util.concurrent.ThreadPoolExecutor$Worker.run(ThreadPoolExecutor.java:628)
at java.base/java.lang.Thread.run(Thread.java:834)
]]>
            </full-stacktrace>
          </exception> <!-- java.lang.AssertionError -->
          <reporter-output>
          </reporter-output>
        </test-method> <!-- Errors -->
        <test-method is-config="true" signature="teardown()[pri:0, instance:Automation4ME.tests.ErrorValidationtest@27d4a09]" started-at="2024-03-20T10:20:17 EDT" name="teardown" finished-at="2024-03-20T10:20:17 EDT" duration-ms="340" status="PASS">
          <reporter-output>
          </reporter-output>
        </test-method> <!-- teardown -->
        <test-method is-config="true" signature="launchApplication()[pri:0, instance:Automation4ME.tests.ErrorValidationtest@27d4a09]" started-at="2024-03-20T10:20:17 EDT" name="launchApplication" finished-at="2024-03-20T10:20:20 EDT" duration-ms="2856" status="PASS">
          <reporter-output>
          </reporter-output>
        </test-method> <!-- launchApplication -->
        <test-method signature="Errors(java.util.HashMap)[pri:0, instance:Automation4ME.tests.ErrorValidationtest@27d4a09]" started-at="2024-03-20T10:20:20 EDT" name="Errors" data-provider="getData1" finished-at="2024-03-20T10:20:20 EDT" duration-ms="493" status="FAIL">
          <params>
            <param index="0">
              <value>
                <![CDATA[{password=secret_sauce, email=standard_user}]]>
              </value>
            </param>
          </params>
          <exception class="java.lang.AssertionError">
            <message>
              <![CDATA[expected [false] but found [true]]]>
            </message>
            <full-stacktrace>
              <![CDATA[java.lang.AssertionError: expected [false] but found [true]
at org.testng.Assert.fail(Assert.java:111)
at org.testng.Assert.failNotEquals(Assert.java:1578)
at org.testng.Assert.assertFalse(Assert.java:79)
at org.testng.Assert.assertFalse(Assert.java:89)
at Automation4ME.tests.ErrorValidationtest.Errors(ErrorValidationtest.java:38)
at java.base/jdk.internal.reflect.NativeMethodAccessorImpl.invoke0(Native Method)
at java.base/jdk.internal.reflect.NativeMethodAccessorImpl.invoke(NativeMethodAccessorImpl.java:62)
at java.base/jdk.internal.reflect.DelegatingMethodAccessorImpl.invoke(DelegatingMethodAccessorImpl.java:43)
at java.base/java.lang.reflect.Method.invoke(Method.java:566)
at org.testng.internal.invokers.MethodInvocationHelper.invokeMethod(MethodInvocationHelper.java:139)
at org.testng.internal.invokers.TestInvoker.invokeMethod(TestInvoker.java:664)
at org.testng.internal.invokers.TestInvoker.retryFailed(TestInvoker.java:249)
at org.testng.internal.invokers.MethodRunner.runInSequence(MethodRunner.java:76)
at org.testng.internal.invokers.TestInvoker$MethodInvocationAgent.invoke(TestInvoker.java:961)
at org.testng.internal.invokers.TestInvoker.invokeTestMethods(TestInvoker.java:201)
at org.testng.internal.invokers.TestMethodWorker.invokeTestMethods(TestMethodWorker.java:148)
at org.testng.internal.invokers.TestMethodWorker.run(TestMethodWorker.java:128)
at java.base/java.util.ArrayList.forEach(ArrayList.java:1541)
at org.testng.TestRunner.privateRun(TestRunner.java:819)
at org.testng.TestRunner.run(TestRunner.java:619)
at org.testng.SuiteRunner.runTest(SuiteRunner.java:443)
at org.testng.SuiteRunner$SuiteWorker.run(SuiteRunner.java:481)
at org.testng.internal.thread.ThreadUtil.lambda$execute$0(ThreadUtil.java:58)
at java.base/java.util.concurrent.FutureTask.run(FutureTask.java:264)
at java.base/java.util.concurrent.ThreadPoolExecutor.runWorker(ThreadPoolExecutor.java:1128)
at java.base/java.util.concurrent.ThreadPoolExecutor$Worker.run(ThreadPoolExecutor.java:628)
at java.base/java.lang.Thread.run(Thread.java:834)
]]>
            </full-stacktrace>
          </exception> <!-- java.lang.AssertionError -->
          <reporter-output>
          </reporter-output>
        </test-method> <!-- Errors -->
        <test-method is-config="true" signature="teardown()[pri:0, instance:Automation4ME.tests.ErrorValidationtest@27d4a09]" started-at="2024-03-20T10:20:21 EDT" name="teardown" finished-at="2024-03-20T10:20:21 EDT" duration-ms="131" status="PASS">
          <reporter-output>
          </reporter-output>
        </test-method> <!-- teardown -->
        <test-method is-config="true" signature="launchApplication()[pri:0, instance:Automation4ME.tests.ErrorValidationtest@27d4a09]" started-at="2024-03-20T10:20:21 EDT" name="launchApplication" finished-at="2024-03-20T10:20:24 EDT" duration-ms="3178" status="PASS">
          <reporter-output>
          </reporter-output>
        </test-method> <!-- launchApplication -->
        <test-method signature="Errors(java.util.HashMap)[pri:0, instance:Automation4ME.tests.ErrorValidationtest@27d4a09]" started-at="2024-03-20T10:20:24 EDT" name="Errors" data-provider="getData1" finished-at="2024-03-20T10:20:25 EDT" duration-ms="462" status="FAIL">
          <params>
            <param index="0">
              <value>
                <![CDATA[{password=secret_sauce, email=standard_user}]]>
              </value>
            </param>
          </params>
          <exception class="java.lang.AssertionError">
            <message>
              <![CDATA[expected [false] but found [true]]]>
            </message>
            <full-stacktrace>
              <![CDATA[java.lang.AssertionError: expected [false] but found [true]
at org.testng.Assert.fail(Assert.java:111)
at org.testng.Assert.failNotEquals(Assert.java:1578)
at org.testng.Assert.assertFalse(Assert.java:79)
at org.testng.Assert.assertFalse(Assert.java:89)
at Automation4ME.tests.ErrorValidationtest.Errors(ErrorValidationtest.java:38)
at java.base/jdk.internal.reflect.NativeMethodAccessorImpl.invoke0(Native Method)
at java.base/jdk.internal.reflect.NativeMethodAccessorImpl.invoke(NativeMethodAccessorImpl.java:62)
at java.base/jdk.internal.reflect.DelegatingMethodAccessorImpl.invoke(DelegatingMethodAccessorImpl.java:43)
at java.base/java.lang.reflect.Method.invoke(Method.java:566)
at org.testng.internal.invokers.MethodInvocationHelper.invokeMethod(MethodInvocationHelper.java:139)
at org.testng.internal.invokers.TestInvoker.invokeMethod(TestInvoker.java:664)
at org.testng.internal.invokers.TestInvoker.invokeTestMethod(TestInvoker.java:228)
at org.testng.internal.invokers.MethodRunner.runInSequence(MethodRunner.java:63)
at org.testng.internal.invokers.TestInvoker$MethodInvocationAgent.invoke(TestInvoker.java:961)
at org.testng.internal.invokers.TestInvoker.invokeTestMethods(TestInvoker.java:201)
at org.testng.internal.invokers.TestMethodWorker.invokeTestMethods(TestMethodWorker.java:148)
at org.testng.internal.invokers.TestMethodWorker.run(TestMethodWorker.java:128)
at java.base/java.util.ArrayList.forEach(ArrayList.java:1541)
at org.testng.TestRunner.privateRun(TestRunner.java:819)
at org.testng.TestRunner.run(TestRunner.java:619)
at org.testng.SuiteRunner.runTest(SuiteRunner.java:443)
at org.testng.SuiteRunner$SuiteWorker.run(SuiteRunner.java:481)
at org.testng.internal.thread.ThreadUtil.lambda$execute$0(ThreadUtil.java:58)
at java.base/java.util.concurrent.FutureTask.run(FutureTask.java:264)
at java.base/java.util.concurrent.ThreadPoolExecutor.runWorker(ThreadPoolExecutor.java:1128)
at java.base/java.util.concurrent.ThreadPoolExecutor$Worker.run(ThreadPoolExecutor.java:628)
at java.base/java.lang.Thread.run(Thread.java:834)
]]>
            </full-stacktrace>
          </exception> <!-- java.lang.AssertionError -->
          <reporter-output>
          </reporter-output>
        </test-method> <!-- Errors -->
        <test-method is-config="true" signature="teardown()[pri:0, instance:Automation4ME.tests.ErrorValidationtest@27d4a09]" started-at="2024-03-20T10:20:25 EDT" name="teardown" finished-at="2024-03-20T10:20:25 EDT" duration-ms="147" status="PASS">
          <reporter-output>
          </reporter-output>
        </test-method> <!-- teardown -->
      </class> <!-- Automation4ME.tests.ErrorValidationtest -->
    </test> <!-- Error Test -->
  </suite> <!-- Suite -->
</testng-results>
